Failure # 1 (occurred at 2025-10-06_23-44-02)
Traceback (most recent call last):
  File "C:\V\Workspace\python\39_ttt\.venv\lib\site-packages\ray\tune\trial_runner.py", line 924, in _process_trial
    results = self.trial_executor.fetch_result(trial)
  File "C:\V\Workspace\python\39_ttt\.venv\lib\site-packages\ray\tune\ray_trial_executor.py", line 787, in fetch_result
    result = ray.get(trial_future[0], timeout=DEFAULT_GET_TIMEOUT)
  File "C:\V\Workspace\python\39_ttt\.venv\lib\site-packages\ray\_private\client_mode_hook.py", line 105, in wrapper
    return func(*args, **kwargs)
  File "C:\V\Workspace\python\39_ttt\.venv\lib\site-packages\ray\worker.py", line 1713, in get
    raise value.as_instanceof_cause()
ray.exceptions.RayTaskError(RuntimeError): [36mray::IMPALA.train()[39m (pid=225824, ip=127.0.0.1, repr=IMPALA)
  File "python\ray\_raylet.pyx", line 625, in ray._raylet.execute_task
  File "python\ray\_raylet.pyx", line 629, in ray._raylet.execute_task
  File "python\ray\_raylet.pyx", line 578, in ray._raylet.execute_task.function_executor
  File "C:\V\Workspace\python\39_ttt\.venv\lib\site-packages\ray\_private\function_manager.py", line 609, in actor_method_executor
    return method(__ray_actor, *args, **kwargs)
  File "C:\V\Workspace\python\39_ttt\.venv\lib\site-packages\ray\util\tracing\tracing_helper.py", line 451, in _resume_span
    return method(self, *_args, **_kwargs)
  File "C:\V\Workspace\python\39_ttt\.venv\lib\site-packages\ray\tune\trainable.py", line 314, in train
    result = self.step()
  File "C:\V\Workspace\python\39_ttt\.venv\lib\site-packages\ray\util\tracing\tracing_helper.py", line 451, in _resume_span
    return method(self, *_args, **_kwargs)
  File "C:\V\Workspace\python\39_ttt\.venv\lib\site-packages\ray\rllib\agents\trainer.py", line 885, in step
    raise e
  File "C:\V\Workspace\python\39_ttt\.venv\lib\site-packages\ray\rllib\agents\trainer.py", line 867, in step
    result = self.step_attempt()
  File "C:\V\Workspace\python\39_ttt\.venv\lib\site-packages\ray\util\tracing\tracing_helper.py", line 451, in _resume_span
    return method(self, *_args, **_kwargs)
  File "C:\V\Workspace\python\39_ttt\.venv\lib\site-packages\ray\rllib\agents\trainer.py", line 920, in step_attempt
    step_results = next(self.train_exec_impl)
  File "C:\V\Workspace\python\39_ttt\.venv\lib\site-packages\ray\util\iter.py", line 756, in __next__
    return next(self.built_iterator)
  File "C:\V\Workspace\python\39_ttt\.venv\lib\site-packages\ray\util\iter.py", line 783, in apply_foreach
    for item in it:
  File "C:\V\Workspace\python\39_ttt\.venv\lib\site-packages\ray\util\iter.py", line 783, in apply_foreach
    for item in it:
  File "C:\V\Workspace\python\39_ttt\.venv\lib\site-packages\ray\util\iter.py", line 843, in apply_filter
    for item in it:
  File "C:\V\Workspace\python\39_ttt\.venv\lib\site-packages\ray\util\iter.py", line 843, in apply_filter
    for item in it:
  File "C:\V\Workspace\python\39_ttt\.venv\lib\site-packages\ray\util\iter.py", line 783, in apply_foreach
    for item in it:
  File "C:\V\Workspace\python\39_ttt\.venv\lib\site-packages\ray\util\iter.py", line 843, in apply_filter
    for item in it:
  File "C:\V\Workspace\python\39_ttt\.venv\lib\site-packages\ray\util\iter.py", line 1075, in build_union
    item = next(it)
  File "C:\V\Workspace\python\39_ttt\.venv\lib\site-packages\ray\util\iter.py", line 756, in __next__
    return next(self.built_iterator)
  File "C:\V\Workspace\python\39_ttt\.venv\lib\site-packages\ray\util\iter.py", line 783, in apply_foreach
    for item in it:
  File "C:\V\Workspace\python\39_ttt\.venv\lib\site-packages\ray\util\iter.py", line 783, in apply_foreach
    for item in it:
  File "C:\V\Workspace\python\39_ttt\.venv\lib\site-packages\ray\rllib\execution\concurrency_ops.py", line 135, in base_iterator
    raise RuntimeError("Dequeue `check()` returned False! "
RuntimeError: Dequeue `check()` returned False! Exiting with Exception from Dequeue iterator.

