Failure # 1 (occurred at 2025-09-20_23-32-42)
Traceback (most recent call last):
  File "C:\V\Workspace\python\39_tt\.venv\lib\site-packages\ray\tune\trial_runner.py", line 924, in _process_trial
    results = self.trial_executor.fetch_result(trial)
  File "C:\V\Workspace\python\39_tt\.venv\lib\site-packages\ray\tune\ray_trial_executor.py", line 787, in fetch_result
    result = ray.get(trial_future[0], timeout=DEFAULT_GET_TIMEOUT)
  File "C:\V\Workspace\python\39_tt\.venv\lib\site-packages\ray\_private\client_mode_hook.py", line 105, in wrapper
    return func(*args, **kwargs)
  File "C:\V\Workspace\python\39_tt\.venv\lib\site-packages\ray\worker.py", line 1713, in get
    raise value.as_instanceof_cause()
ray.exceptions.RayTaskError(ValueError): [36mray::A3C.train()[39m (pid=73868, ip=127.0.0.1, repr=A3C)
  File "python\ray\_raylet.pyx", line 625, in ray._raylet.execute_task
  File "python\ray\_raylet.pyx", line 629, in ray._raylet.execute_task
  File "python\ray\_raylet.pyx", line 578, in ray._raylet.execute_task.function_executor
  File "C:\V\Workspace\python\39_tt\.venv\lib\site-packages\ray\_private\function_manager.py", line 609, in actor_method_executor
    return method(__ray_actor, *args, **kwargs)
  File "C:\V\Workspace\python\39_tt\.venv\lib\site-packages\ray\util\tracing\tracing_helper.py", line 451, in _resume_span
    return method(self, *_args, **_kwargs)
  File "C:\V\Workspace\python\39_tt\.venv\lib\site-packages\ray\tune\trainable.py", line 314, in train
    result = self.step()
  File "C:\V\Workspace\python\39_tt\.venv\lib\site-packages\ray\util\tracing\tracing_helper.py", line 451, in _resume_span
    return method(self, *_args, **_kwargs)
  File "C:\V\Workspace\python\39_tt\.venv\lib\site-packages\ray\rllib\agents\trainer.py", line 880, in step
    raise e
  File "C:\V\Workspace\python\39_tt\.venv\lib\site-packages\ray\rllib\agents\trainer.py", line 867, in step
    result = self.step_attempt()
  File "C:\V\Workspace\python\39_tt\.venv\lib\site-packages\ray\util\tracing\tracing_helper.py", line 451, in _resume_span
    return method(self, *_args, **_kwargs)
  File "C:\V\Workspace\python\39_tt\.venv\lib\site-packages\ray\rllib\agents\trainer.py", line 920, in step_attempt
    step_results = next(self.train_exec_impl)
  File "C:\V\Workspace\python\39_tt\.venv\lib\site-packages\ray\util\iter.py", line 756, in __next__
    return next(self.built_iterator)
  File "C:\V\Workspace\python\39_tt\.venv\lib\site-packages\ray\util\iter.py", line 783, in apply_foreach
    for item in it:
  File "C:\V\Workspace\python\39_tt\.venv\lib\site-packages\ray\util\iter.py", line 843, in apply_filter
    for item in it:
  File "C:\V\Workspace\python\39_tt\.venv\lib\site-packages\ray\util\iter.py", line 843, in apply_filter
    for item in it:
  File "C:\V\Workspace\python\39_tt\.venv\lib\site-packages\ray\util\iter.py", line 783, in apply_foreach
    for item in it:
  File "C:\V\Workspace\python\39_tt\.venv\lib\site-packages\ray\util\iter.py", line 828, in add_wait_hooks
    item = next(it)
  File "C:\V\Workspace\python\39_tt\.venv\lib\site-packages\ray\util\iter.py", line 783, in apply_foreach
    for item in it:
  File "C:\V\Workspace\python\39_tt\.venv\lib\site-packages\ray\util\iter.py", line 551, in base_iterator
    batch = ray.get(obj_ref)
  File "C:\V\Workspace\python\39_tt\.venv\lib\site-packages\ray\_private\client_mode_hook.py", line 105, in wrapper
    return func(*args, **kwargs)
  File "C:\V\Workspace\python\39_tt\.venv\lib\site-packages\ray\worker.py", line 1713, in get
    raise value.as_instanceof_cause()
ray.exceptions.RayTaskError(ValueError): [36mray::RolloutWorker.par_iter_next_batch()[39m (pid=47964, ip=127.0.0.1, repr=<ray.rllib.evaluation.rollout_worker.RolloutWorker object at 0x0000015FADB8CE80>)
  File "python\ray\_raylet.pyx", line 625, in ray._raylet.execute_task
  File "python\ray\_raylet.pyx", line 629, in ray._raylet.execute_task
  File "python\ray\_raylet.pyx", line 578, in ray._raylet.execute_task.function_executor
  File "C:\V\Workspace\python\39_tt\.venv\lib\site-packages\ray\_private\function_manager.py", line 609, in actor_method_executor
    return method(__ray_actor, *args, **kwargs)
  File "C:\V\Workspace\python\39_tt\.venv\lib\site-packages\ray\util\tracing\tracing_helper.py", line 451, in _resume_span
    return method(self, *_args, **_kwargs)
  File "C:\V\Workspace\python\39_tt\.venv\lib\site-packages\ray\util\iter.py", line 1157, in par_iter_next_batch
    batch.append(self.par_iter_next())
  File "C:\V\Workspace\python\39_tt\.venv\lib\site-packages\ray\util\tracing\tracing_helper.py", line 451, in _resume_span
    return method(self, *_args, **_kwargs)
  File "C:\V\Workspace\python\39_tt\.venv\lib\site-packages\ray\util\iter.py", line 1151, in par_iter_next
    return next(self.local_it)
  File "C:\V\Workspace\python\39_tt\.venv\lib\site-packages\ray\util\iter.py", line 783, in apply_foreach
    for item in it:
  File "C:\V\Workspace\python\39_tt\.venv\lib\site-packages\ray\rllib\evaluation\rollout_worker.py", line 381, in gen_rollouts
    yield self.sample()
  File "C:\V\Workspace\python\39_tt\.venv\lib\site-packages\ray\util\tracing\tracing_helper.py", line 451, in _resume_span
    return method(self, *_args, **_kwargs)
  File "C:\V\Workspace\python\39_tt\.venv\lib\site-packages\ray\rllib\evaluation\rollout_worker.py", line 757, in sample
    batches = [self.input_reader.next()]
  File "C:\V\Workspace\python\39_tt\.venv\lib\site-packages\ray\rllib\evaluation\sampler.py", line 103, in next
    batches = [self.get_data()]
  File "C:\V\Workspace\python\39_tt\.venv\lib\site-packages\ray\rllib\evaluation\sampler.py", line 457, in get_data
    raise rollout
  File "C:\Users\пя\AppData\Local\Programs\Python\Python39\lib\threading.py", line 980, in _bootstrap_inner
    self.run()
  File "C:\V\Workspace\python\39_tt\.venv\lib\site-packages\ray\rllib\evaluation\sampler.py", line 423, in run
    raise e
  File "C:\V\Workspace\python\39_tt\.venv\lib\site-packages\ray\rllib\evaluation\sampler.py", line 420, in run
    self._run()
  File "C:\V\Workspace\python\39_tt\.venv\lib\site-packages\ray\rllib\evaluation\sampler.py", line 443, in _run
    item = next(env_runner)
  File "C:\V\Workspace\python\39_tt\.venv\lib\site-packages\ray\rllib\evaluation\sampler.py", line 656, in _env_runner
    eval_results = _do_policy_eval(
  File "C:\V\Workspace\python\39_tt\.venv\lib\site-packages\ray\rllib\evaluation\sampler.py", line 1070, in _do_policy_eval
    policy.compute_actions_from_input_dict(
  File "C:\V\Workspace\python\39_tt\.venv\lib\site-packages\ray\rllib\policy\torch_policy.py", line 294, in compute_actions_from_input_dict
    return self._compute_action_helper(input_dict, state_batches,
  File "C:\V\Workspace\python\39_tt\.venv\lib\site-packages\ray\rllib\utils\threading.py", line 21, in wrapper
    return func(self, *a, **k)
  File "C:\V\Workspace\python\39_tt\.venv\lib\site-packages\ray\rllib\policy\torch_policy.py", line 944, in _compute_action_helper
    action_dist = dist_class(dist_inputs, self.model)
  File "C:\V\Workspace\python\39_tt\.venv\lib\site-packages\ray\rllib\models\torch\torch_action_dist.py", line 185, in __init__
    self.dist = torch.distributions.normal.Normal(mean, torch.exp(log_std))
  File "C:\V\Workspace\python\39_tt\.venv\lib\site-packages\torch\distributions\normal.py", line 50, in __init__
    super(Normal, self).__init__(batch_shape, validate_args=validate_args)
  File "C:\V\Workspace\python\39_tt\.venv\lib\site-packages\torch\distributions\distribution.py", line 55, in __init__
    raise ValueError(
ValueError: Expected parameter loc (Tensor of shape (1, 2)) of distribution Normal(loc: torch.Size([1, 2]), scale: torch.Size([1, 2])) to satisfy the constraint Real(), but found invalid values:
tensor([[nan, nan]])

